our classifier is not working well, theres no way a deleted deployment sjhould be information and thats because theres no reason available

we should be able to do something 
def classify_event(reason: str) -> str:
    if reason in ["CrashLoopBackOff", "OOMKilled", "ImagePullBackOff", "NodeNotReady"]:
        return "critical"
    elif reason in ["BackOff", "Unhealthy", "IngressBackendNotFound"]:
        return "important"
    else:
        return "informational"



and why is my od showing this 2025-09-10 19:59:24,004 [ERROR] Exception in callback _chain_future.<locals>._set_state(<Future pendi...ask_wakeup()]>, <Future at 0x...StopIteration>) at /home/muhammad/.pyenv/versions/3.12.4/lib/python3.12/asyncio/futures.py:381
handle: <Handle _chain_future.<locals>._set_state(<Future pendi...ask_wakeup()]>, <Future at 0x...StopIteration>) at /home/muhammad/.pyenv/versions/3.12.4/lib/python3.12/asyncio/futures.py:381>
Traceback (most recent call last):
  File "/home/muhammad/.pyenv/versions/3.12.4/lib/python3.12/asyncio/events.py", line 88, in _run
    self._context.run(self._callback, *self._args)
  File "/home/muhammad/.pyenv/versions/3.12.4/lib/python3.12/asyncio/futures.py", line 383, in _set_state
    _copy_future_state(other, future)
  File "/home/muhammad/.pyenv/versions/3.12.4/lib/python3.12/asyncio/futures.py", line 359, in _copy_future_state
    dest.set_exception(_convert_future_exc(exception))
TypeError: StopIteration interacts badly with generators and cannot be raised into a Future
2025-09-10 19:59:24,011 [ERROR] Exception in callback _chain_future.<locals>._set_state(<Future pendi...ask_wakeup()]>, <Future at 0x...StopIteration>) at /home/muhammad/.pyenv/versions/3.12.4/lib/python3.12/asyncio/futures.py:381
handle: <Handle _chain_future.<locals>._set_state(<Future pendi...ask_wakeup()]>, <Future at 0x...StopIteration>) at /home/muhammad/.pyenv/versions/3.12.4/lib/python3.12/asyncio/futures.py:381>
Traceback (most recent call last):
  File "/home/muhammad/.pyenv/versions/3.12.4/lib/python3.12/asyncio/events.py", line 88, in _run
    self._context.run(self._callback, *self._args)
  File "/home/muhammad/.pyenv/versions/3.12.4/lib/python3.12/asyncio/futures.py", line 383, in _set_state
    _copy_future_state(other, future)
  File "/home/muhammad/.pyenv/versions/3.12.4/lib/python3.12/asyncio/futures.py", line 359, in _copy_future_state
    dest.set_exception(_convert_future_exc(exception))
TypeError: StopIteration interacts badly with generators and cannot be raised into a Future
2025-09-10 19:59:24,014 [ERROR] Exception in callback _chain_future.<locals>._set_state(<Future pendi...ask_wakeup()]>, <Future at 0x...StopIteration>) at /home/muhammad/.pyenv/versions/3.12.4/lib/python3.12/asyncio/futures.py:381
handle: <Handle _chain_future.<locals>._set_state(<Future pendi...ask_wakeup()]>, <Future at 0x...StopIteration>) at /home/muhammad/.pyenv/versions/3.12.4/lib/python3.12/asyncio/futures.py:381>
Traceback (most recent call last):
  File "/home/muhammad/.pyenv/versions/3.12.4/lib/python3.12/asyncio/events.py", line 88, in _run
    self._context.run(self._callback, *self._args)
  File "/home/muhammad/.pyenv/versions/3.12.4/lib/python3.12/asyncio/futures.py", line 383, in _set_state
    _copy_future_state(other, future)
  File "/home/muhammad/.pyenv/versions/3.12.4/lib/python3.12/asyncio/futures.py", line 359, in _copy_future_state
    dest.set_exception(_convert_future_exc(exception))
TypeError: StopIteration interacts badly with generators and cannot be raised into a Future
2025-09-10 19:59:24,035 [ERROR] Exception in callback _chain_future.<locals>._set_state(<Future pendi...ask_wakeup()]>, <Future at 0x...StopIteration>) at /home/muhammad/.pyenv/versions/3.12.4/lib/python3.12/asyncio/futures.py:381
handle: <Handle _chain_future.<locals>._set_state(<Future pendi...ask_wakeup()]>, <Future at 0x...StopIteration>) at /home/muhammad/.pyenv/versions/3.12.4/lib/python3.12/asyncio/futures.py:381>
Traceback (most recent call last):
  File "/home/muhammad/.pyenv/versions/3.12.4/lib/python3.12/asyncio/events.py", line 88, in _run
    self._context.run(self._callback, *self._args)
  File "/home/muhammad/.pyenv/versions/3.12.4/lib/python3.12/asyncio/futures.py", line 383, in _set_state
    _copy_future_state(other, future)
  File "/home/muhammad/.pyenv/versions/3.12.4/lib/python3.12/asyncio/futures.py", line 359, in _copy_future_state
    dest.set_exception(_convert_future_exc(exception))
TypeError: StopIteration interacts badly with generators and cannot be raised into a Future
2025-09-10 19:59:24,046 [ERROR] Exception in callback _chain_future.<locals>._set_state(<Future pendi...ask_wakeup()]>, <Future at 0x...StopIteration>) at /home/muhammad/.pyenv/versions/3.12.4/lib/python3.12/asyncio/futures.py:381
handle: <Handle _chain_future.<locals>._set_state(<Future pendi...ask_wakeup()]>, <Future at 0x...StopIteration>) at /home/muhammad/.pyenv/versions/3.12.4/lib/python3.12/asyncio/futures.py:381>
Traceback (most recent call last):
  File "/home/muhammad/.pyenv/versions/3.12.4/lib/python3.12/asyncio/events.py", line 88, in _run
    self._context.run(self._callback, *self._args)
  File "/home/muhammad/.pyenv/versions/3.12.4/lib/python3.12/asyncio/futures.py", line 383, in _set_state
    _copy_future_state(other, future)
  File "/home/muhammad/.pyenv/versions/3.12.4/lib/python3.12/asyncio/futures.py", line 359, in _copy_future_state
    dest.set_exception(_convert_future_exc(exception))
TypeError: StopIteration interacts badly with generators and cannot be raised into a Future
2025-09-10 19:59:24,052 [ERROR] Exception in callback _chain_future.<locals>._set_state(<Future pendi...ask_wakeup()]>, <Future at 0x...StopIteration>) at /home/muhammad/.pyenv/versions/3.12.4/lib/python3.12/asyncio/futures.py:381
handle: <Handle _chain_future.<locals>._set_state(<Future pendi...ask_wakeup()]>, <Future at 0x...StopIteration>) at /home/muhammad/.pyenv/versions/3.12.4/lib/python3.12/asyncio/futures.py:381>
Traceback (most recent call last):
  File "/home/muhammad/.pyenv/versions/3.12.4/lib/python3.12/asyncio/events.py", line 88, in _run
    self._context.run(self._callback, *self._args)
  File "/home/muhammad/.pyenv/versions/3.12.4/lib/python3.12/asyncio/futures.py", line 383, in _set_state
    _copy_future_state(other, future)
  File "/home/muhammad/.pyenv/versions/3.12.4/lib/python3.12/asyncio/futures.py", line 359, in _copy_future_state
    dest.set_exception(_convert_future_exc(exception))
TypeError: StopIteration interacts badly with generators and cannot be raised into a Future
2025-09-10 19:59:24,055 [ERROR] Exception in callback _chain_future.<locals>._set_state(<Future pendi...ask_wakeup()]>, <Future at 0x...StopIteration>) at /home/muhammad/.pyenv/versions/3.12.4/lib/python3.12/asyncio/futures.py:381
handle: <Handle _chain_future.<locals>._set_state(<Future pendi...ask_wakeup()]>, <Future at 0x...StopIteration>) at /home/muhammad/.pyenv/versions/3.12.4/lib/python3.12/asyncio/futures.py:381>
Traceback (most recent call last):
  File "/home/muhammad/.pyenv/versions/3.12.4/lib/python3.12/asyncio/events.py", line 88, in _run
    self._context.run(self._callback, *self._args)
  File "/home/muhammad/.pyenv/versions/3.12.4/lib/python3.12/asyncio/futures.py", line 383, in _set_state
    _copy_future_state(other, future)
  File "/home/muhammad/.pyenv/versions/3.12.4/lib/python3.12/asyncio/futures.py", line 359, in _copy_future_state
    dest.set_exception(_convert_future_exc(exception))
TypeError: StopIteration interacts badly with generators and cannot be raised into a Future
2025-09-10 19:59:24,063 [ERROR] Exception in callback _chain_future.<locals>._set_state(<Future pendi...ask_wakeup()]>, <Future at 0x...StopIteration>) at /home/muhammad/.pyenv/versions/3.12.4/lib/python3.12/asyncio/futures.py:381
handle: <Handle _chain_future.<locals>._set_state(<Future pendi...ask_wakeup()]>, <Future at 0x...StopIteration>) at /home/muhammad/.pyenv/versions/3.12.4/lib/python3.12/asyncio/futures.py:381>
Traceback (most recent call last):
  File "/home/muhammad/.pyenv/versions/3.12.4/lib/python3.12/asyncio/events.py", line 88, in _run
    self._context.run(self._callback, *self._args)
  File "/home/muhammad/.pyenv/versions/3.12.4/lib/python3.12/asyncio/futures.py", line 383, in _set_state
    _copy_future_state(other, future)
  File "/home/muhammad/.pyenv/versions/3.12.4/lib/python3.12/asyncio/futures.py", line 359, in _copy_future_state
    dest.set_exception(_convert_future_exc(exception))
TypeError: StopIteration interacts badly with generators and cannot be raised into a Future
2025-09-10 19:59:24,071 [ERROR] Exception in callback _chain_future.<locals>._set_state(<Future pendi...ask_wakeup()]>, <Future at 0x...StopIteration>) at /home/muhammad/.pyenv/versions/3.12.4/lib/python3.12/asyncio/futures.py:381
handle: <Handle _chain_future.<locals>._set_state(<Future pendi...ask_wakeup()]>, <Future at 0x...StopIteration>) at /home/muhammad/.pyenv/versions/3.12.4/lib/python3.12/asyncio/futures.py:381>
Traceback (most recent call last):
  File "/home/muhammad/.pyenv/versions/3.12.4/lib/python3.12/asyncio/events.py", line 88, in _run
    self._context.run(self._callback, *self._args)
  File "/home/muhammad/.pyenv/versions/3.12.4/lib/python3.12/asyncio/futures.py", line 383, in _set_state
    _copy_future_state(other, future)
  File "/home/muhammad/.pyenv/versions/3.12.4/lib/python3.12/asyncio/futures.py", line 359, in _copy_future_state
    dest.set_exception(_convert_future_exc(exception))
TypeError: StopIteration interacts badly with generators and cannot be raised into a Future
